NEW ERROR

Traceback (most recent call last):
  File "C:\Users\rchir\OneDrive\Desktop\Pixel-bot-2.0\events\error_handler.py", line 260, in on_slash_command_error
    raise error
  File "C:\Users\rchir\AppData\Local\Programs\Python\Python39\lib\site-packages\discord_slash\client.py", line 1352, in invoke_command
    await func.invoke(ctx, **args)
  File "C:\Users\rchir\AppData\Local\Programs\Python\Python39\lib\site-packages\discord_slash\model.py", line 209, in invoke
    return await self.func(self.cog, *args, **kwargs)
  File "C:\Users\rchir\OneDrive\Desktop\Pixel-bot-2.0\commands\restricted.py", line 183, in _raise
    raise ValueError
ValueError
NEW ERROR

Traceback (most recent call last):
  File "C:\Users\rchir\OneDrive\Desktop\Pixel-bot-2.0\events\error_handler.py", line 260, in on_slash_command_error
    raise error
  File "C:\Users\rchir\AppData\Local\Programs\Python\Python39\lib\site-packages\discord_slash\client.py", line 1352, in invoke_command
    await func.invoke(ctx, **args)
  File "C:\Users\rchir\AppData\Local\Programs\Python\Python39\lib\site-packages\discord_slash\model.py", line 209, in invoke
    return await self.func(self.cog, *args, **kwargs)
  File "C:\Users\rchir\OneDrive\Desktop\Pixel-bot-2.0\commands\restricted.py", line 186, in _raise
    raise ValueError(error_message)
ValueError: Hello
NEW ERROR

Traceback (most recent call last):
  File "C:\Users\rchir\OneDrive\Desktop\Pixel-bot-2.0\events\error_handler.py", line 260, in on_slash_command_error
    raise error
  File "C:\Users\rchir\AppData\Local\Programs\Python\Python39\lib\site-packages\discord_slash\client.py", line 1352, in invoke_command
    await func.invoke(ctx, **args)
  File "C:\Users\rchir\AppData\Local\Programs\Python\Python39\lib\site-packages\discord_slash\model.py", line 209, in invoke
    return await self.func(self.cog, *args, **kwargs)
  File "C:\Users\rchir\OneDrive\Desktop\Pixel-bot-2.0\commands\restricted.py", line 186, in _raise
    raise ValueError(error_message)
ValueError: Testing
NEW ERROR

Traceback (most recent call last):
  File "C:\Users\rchir\OneDrive\Desktop\Pixel-bot-2.0\events\error_handler.py", line 260, in on_slash_command_error
    raise error
  File "C:\Users\rchir\AppData\Local\Programs\Python\Python39\lib\site-packages\discord_slash\client.py", line 1352, in invoke_command
    await func.invoke(ctx, **args)
  File "C:\Users\rchir\AppData\Local\Programs\Python\Python39\lib\site-packages\discord_slash\model.py", line 209, in invoke
    return await self.func(self.cog, *args, **kwargs)
  File "C:\Users\rchir\OneDrive\Desktop\Pixel-bot-2.0\commands\restricted.py", line 186, in _raise
    raise ValueError(error_message)
ValueError: WA
NEW ERROR

Traceback (most recent call last):
  File "C:\Users\rchir\OneDrive\Desktop\Pixel-bot-2.0\events\error_handler.py", line 260, in on_slash_command_error
    raise error
  File "C:\Users\rchir\AppData\Local\Programs\Python\Python39\lib\site-packages\discord_slash\client.py", line 1352, in invoke_command
    await func.invoke(ctx, **args)
  File "C:\Users\rchir\AppData\Local\Programs\Python\Python39\lib\site-packages\discord_slash\model.py", line 209, in invoke
    return await self.func(self.cog, *args, **kwargs)
  File "C:\Users\rchir\OneDrive\Desktop\Pixel-bot-2.0\commands\restricted.py", line 186, in _raise
    raise ValueError(error_message)
ValueError: yes
NEW ERROR

Traceback (most recent call last):
  File "C:\Users\rchir\OneDrive\Desktop\Pixel-bot-2.0\events\error_handler.py", line 260, in on_slash_command_error
    raise error
  File "C:\Users\rchir\AppData\Local\Programs\Python\Python39\lib\site-packages\discord_slash\client.py", line 1352, in invoke_command
    await func.invoke(ctx, **args)
  File "C:\Users\rchir\AppData\Local\Programs\Python\Python39\lib\site-packages\discord_slash\model.py", line 209, in invoke
    return await self.func(self.cog, *args, **kwargs)
  File "C:\Users\rchir\OneDrive\Desktop\Pixel-bot-2.0\commands\restricted.py", line 186, in _raise
    raise ValueError(error_message)
ValueError: a
NEW ERROR

Traceback (most recent call last):
  File "C:\Users\rchir\OneDrive\Desktop\Pixel-bot-2.0\events\error_handler.py", line 260, in on_slash_command_error
    raise error
  File "C:\Users\rchir\AppData\Local\Programs\Python\Python39\lib\site-packages\discord_slash\client.py", line 1352, in invoke_command
    await func.invoke(ctx, **args)
  File "C:\Users\rchir\AppData\Local\Programs\Python\Python39\lib\site-packages\discord_slash\model.py", line 209, in invoke
    return await self.func(self.cog, *args, **kwargs)
  File "C:\Users\rchir\OneDrive\Desktop\Pixel-bot-2.0\commands\restricted.py", line 186, in _raise
    raise ValueError(error_message)
ValueError: YES
NEW ERROR

Traceback (most recent call last):
  File "C:\Users\rchir\OneDrive\Desktop\Pixel-bot-2.0\events\error_handler.py", line 260, in on_slash_command_error
    raise error
  File "C:\Users\rchir\AppData\Local\Programs\Python\Python39\lib\site-packages\discord_slash\client.py", line 1352, in invoke_command
    await func.invoke(ctx, **args)
  File "C:\Users\rchir\AppData\Local\Programs\Python\Python39\lib\site-packages\discord_slash\model.py", line 209, in invoke
    return await self.func(self.cog, *args, **kwargs)
  File "C:\Users\rchir\OneDrive\Desktop\Pixel-bot-2.0\commands\restricted.py", line 186, in _raise
    raise ValueError(error_message)
ValueError: Wakanda FOREVER
NEW ERROR

Traceback (most recent call last):
  File "C:\Users\rchir\OneDrive\Desktop\Pixel-bot-2.0\events\error_handler.py", line 260, in on_slash_command_error
    raise error
  File "C:\Users\rchir\AppData\Local\Programs\Python\Python39\lib\site-packages\discord_slash\client.py", line 1352, in invoke_command
    await func.invoke(ctx, **args)
  File "C:\Users\rchir\AppData\Local\Programs\Python\Python39\lib\site-packages\discord_slash\model.py", line 209, in invoke
    return await self.func(self.cog, *args, **kwargs)
  File "C:\Users\rchir\OneDrive\Desktop\Pixel-bot-2.0\commands\restricted.py", line 186, in _raise
    raise ValueError(error_message)
ValueError: WATCH IT KID
NEW ERROR

Traceback (most recent call last):
  File "C:\Users\rchir\OneDrive\Desktop\Pixel-bot-2.0\events\error_handler.py", line 260, in on_slash_command_error
    raise error
  File "C:\Users\rchir\AppData\Local\Programs\Python\Python39\lib\site-packages\discord_slash\client.py", line 1352, in invoke_command
    await func.invoke(ctx, **args)
  File "C:\Users\rchir\AppData\Local\Programs\Python\Python39\lib\site-packages\discord_slash\model.py", line 209, in invoke
    return await self.func(self.cog, *args, **kwargs)
  File "C:\Users\rchir\OneDrive\Desktop\Pixel-bot-2.0\commands\restricted.py", line 187, in _raise_error
    raise ValueError(error_message)
ValueError: No error message
NEW ERROR

Traceback (most recent call last):
  File "C:\Users\rchir\OneDrive\Desktop\Pixel-bot-2.0\events\error_handler.py", line 260, in on_slash_command_error
    raise error
  File "C:\Users\rchir\AppData\Local\Programs\Python\Python39\lib\site-packages\discord_slash\client.py", line 1352, in invoke_command
    await func.invoke(ctx, **args)
  File "C:\Users\rchir\AppData\Local\Programs\Python\Python39\lib\site-packages\discord_slash\model.py", line 209, in invoke
    return await self.func(self.cog, *args, **kwargs)
  File "C:\Users\rchir\OneDrive\Desktop\Pixel-bot-2.0\commands\level_system.py", line 250, in _level
    f"ðŸ¥³ Total xp: **{await self.client.round_int(total_xp)}**".center(30) + "\n"
  File "C:\Users\rchir\OneDrive\Desktop\Pixel-bot-2.0\main.py", line 174, in round_int
    if my_val >= 1000000000000:
TypeError: '>=' not supported between instances of 'str' and 'int'
NEW ERROR

Traceback (most recent call last):
  File "C:\Users\rchir\OneDrive\Desktop\Pixel-bot-2.0\events\error_handler.py", line 260, in on_slash_command_error
    raise error
  File "C:\Users\rchir\AppData\Local\Programs\Python\Python39\lib\site-packages\discord_slash\client.py", line 1352, in invoke_command
    await func.invoke(ctx, **args)
  File "C:\Users\rchir\AppData\Local\Programs\Python\Python39\lib\site-packages\discord_slash\model.py", line 209, in invoke
    return await self.func(self.cog, *args, **kwargs)
  File "C:\Users\rchir\OneDrive\Desktop\Pixel-bot-2.0\commands\level_system.py", line 333, in disable_xp
    self.client.lvlsys_config[str(ctx.guild_id)]["disabled_channels"].append(channel.id)
KeyError: 'disabled_channels'
NEW ERROR

Traceback (most recent call last):
  File "C:\Users\rchir\OneDrive\Desktop\Pixel-bot-2.0\events\error_handler.py", line 260, in on_slash_command_error
    raise error
  File "C:\Users\rchir\AppData\Local\Programs\Python\Python39\lib\site-packages\discord_slash\client.py", line 1352, in invoke_command
    await func.invoke(ctx, **args)
  File "C:\Users\rchir\AppData\Local\Programs\Python\Python39\lib\site-packages\discord_slash\model.py", line 209, in invoke
    return await self.func(self.cog, *args, **kwargs)
  File "C:\Users\rchir\OneDrive\Desktop\Pixel-bot-2.0\commands\level_system.py", line 336, in disable_xp
    self.client.lvlsys_config[str(ctx.guild_id)]["disabled_channels"].append(channel.id)
KeyError: 'disabled_channels'
NEW ERROR

Traceback (most recent call last):
  File "C:\Users\rchir\OneDrive\Desktop\Pixel-bot-2.0\events\error_handler.py", line 261, in on_slash_command_error
    raise error
  File "C:\Users\rchir\AppData\Local\Programs\Python\Python39\lib\site-packages\discord_slash\client.py", line 1352, in invoke_command
    await func.invoke(ctx, **args)
  File "C:\Users\rchir\AppData\Local\Programs\Python\Python39\lib\site-packages\discord_slash\model.py", line 209, in invoke
    return await self.func(self.cog, *args, **kwargs)
  File "C:\Users\rchir\OneDrive\Desktop\Pixel-bot-2.0\commands\level_system.py", line 420, in xp_event
    with open("data/level_syste/config.json", "w") as f:
FileNotFoundError: [Errno 2] No such file or directory: 'data/level_syste/config.json'
NEW ERROR

Traceback (most recent call last):
  File "C:\Users\rchir\OneDrive\Desktop\Pixel-bot-2.0\events\error_handler.py", line 264, in on_slash_command_error
    raise error
  File "C:\Users\rchir\AppData\Local\Programs\Python\Python39\lib\site-packages\discord_slash\client.py", line 1352, in invoke_command
    await func.invoke(ctx, **args)
  File "C:\Users\rchir\AppData\Local\Programs\Python\Python39\lib\site-packages\discord_slash\model.py", line 209, in invoke
    return await self.func(self.cog, *args, **kwargs)
  File "C:\Users\rchir\OneDrive\Desktop\Pixel-bot-2.0\commands\level_system.py", line 380, in enable_xp
    self.client.lvlsys_config[str(ctx.guild_id)]["disabled_channels"].remove(channel.id)
ValueError: list.remove(x): x not in list
NEW ERROR

Traceback (most recent call last):
  File "C:\Users\rchir\OneDrive\Desktop\Pixel-bot-2.0\events\error_handler.py", line 264, in on_slash_command_error
    raise error
  File "C:\Users\rchir\AppData\Local\Programs\Python\Python39\lib\site-packages\discord_slash\client.py", line 1352, in invoke_command
    await func.invoke(ctx, **args)
  File "C:\Users\rchir\AppData\Local\Programs\Python\Python39\lib\site-packages\discord_slash\model.py", line 209, in invoke
    return await self.func(self.cog, *args, **kwargs)
  File "C:\Users\rchir\OneDrive\Desktop\Pixel-bot-2.0\commands\level_system.py", line 424, in xp_event
    json.dump(self.client.lvlsys_data, f, indent=2)
AttributeError: 'MyClient' object has no attribute 'lvlsys_data'
NEW ERROR

Traceback (most recent call last):
  File "C:\Users\rchir\OneDrive\Desktop\Pixel-bot-2.0\events\error_handler.py", line 264, in on_slash_command_error
    raise error
  File "C:\Users\rchir\AppData\Local\Programs\Python\Python39\lib\site-packages\discord_slash\client.py", line 1352, in invoke_command
    await func.invoke(ctx, **args)
  File "C:\Users\rchir\AppData\Local\Programs\Python\Python39\lib\site-packages\discord_slash\model.py", line 209, in invoke
    return await self.func(self.cog, *args, **kwargs)
  File "C:\Users\rchir\OneDrive\Desktop\Pixel-bot-2.0\commands\level_system.py", line 441, in xp_event
    await ctx.channel.send(f"ðŸŽ‰ **A XP event is starting. From now until** <t:{int(datetime.utcnow().timestamp() + duration)}> **you will receive {xp_per_message} xp per message!** ðŸ¥³ " + ping, allowed_mentions=discord.Role)
  File "C:\Users\rchir\AppData\Local\Programs\Python\Python39\lib\site-packages\discord_slash\dpy_overrides.py", line 323, in send_override
    return await send(channel, *args, **kwargs)
  File "C:\Users\rchir\AppData\Local\Programs\Python\Python39\lib\site-packages\discord_slash\dpy_overrides.py", line 238, in send
    allowed_mentions = state.allowed_mentions.merge(allowed_mentions).to_dict()
  File "C:\Users\rchir\AppData\Local\Programs\Python\Python39\lib\site-packages\discord\mentions.py", line 120, in merge
    everyone = self.everyone if other.everyone is default else other.everyone
AttributeError: type object 'Role' has no attribute 'everyone'
NEW ERROR

Traceback (most recent call last):
  File "C:\Users\rchir\OneDrive\Desktop\Pixel-bot-2.0\events\error_handler.py", line 266, in on_slash_command_error
    raise error
  File "C:\Users\rchir\AppData\Local\Programs\Python\Python39\lib\site-packages\discord_slash\client.py", line 1352, in invoke_command
    await func.invoke(ctx, **args)
  File "C:\Users\rchir\AppData\Local\Programs\Python\Python39\lib\site-packages\discord_slash\model.py", line 209, in invoke
    return await self.func(self.cog, *args, **kwargs)
  File "C:\Users\rchir\OneDrive\Desktop\Pixel-bot-2.0\commands\restricted.py", line 187, in _raise_error
    raise ValueError(error_message)
ValueError: No error message
NEW ERROR

Traceback (most recent call last):
  File "C:\Users\rchir\OneDrive\Desktop\Pixel-bot-2.0\events\error_handler.py", line 266, in on_slash_command_error
    raise error
  File "C:\Users\rchir\AppData\Local\Programs\Python\Python39\lib\site-packages\discord_slash\client.py", line 1352, in invoke_command
    await func.invoke(ctx, **args)
  File "C:\Users\rchir\AppData\Local\Programs\Python\Python39\lib\site-packages\discord_slash\model.py", line 209, in invoke
    return await self.func(self.cog, *args, **kwargs)
  File "C:\Users\rchir\OneDrive\Desktop\Pixel-bot-2.0\commands\restricted.py", line 185, in _raise_error
    raise ValueError(error_message)
ValueError: No error message
NEW ERROR

Traceback (most recent call last):
  File "C:\Users\rchir\OneDrive\Desktop\Pixel-bot-2.0\events\error_handler.py", line 266, in on_slash_command_error
    raise error
  File "C:\Users\rchir\AppData\Local\Programs\Python\Python39\lib\site-packages\discord_slash\client.py", line 1353, in invoke_command
    await func.invoke(ctx, **args)
  File "C:\Users\rchir\AppData\Local\Programs\Python\Python39\lib\site-packages\discord_slash\model.py", line 209, in invoke
    return await self.func(self.cog, *args, **kwargs)
TypeError: verify() got an unexpected keyword argument 'everyone'
NEW ERROR

Traceback (most recent call last):
  File "C:\Users\rchir\OneDrive\Desktop\Pixel-bot-2.0\events\error_handler.py", line 266, in on_slash_command_error
    raise error
  File "C:\Users\rchir\AppData\Local\Programs\Python\Python39\lib\site-packages\discord_slash\client.py", line 1353, in invoke_command
    await func.invoke(ctx, **args)
  File "C:\Users\rchir\AppData\Local\Programs\Python\Python39\lib\site-packages\discord_slash\model.py", line 209, in invoke
    return await self.func(self.cog, *args, **kwargs)
TypeError: verify() got an unexpected keyword argument 'everyone'
NEW ERROR

Traceback (most recent call last):
  File "C:\Users\rchir\OneDrive\Desktop\Pixel-bot-2.0\events\error_handler.py", line 266, in on_slash_command_error
    raise error
  File "C:\Users\rchir\AppData\Local\Programs\Python\Python39\lib\site-packages\discord_slash\client.py", line 1353, in invoke_command
    await func.invoke(ctx, **args)
  File "C:\Users\rchir\AppData\Local\Programs\Python\Python39\lib\site-packages\discord_slash\model.py", line 209, in invoke
    return await self.func(self.cog, *args, **kwargs)
  File "C:\Users\rchir\OneDrive\Desktop\Pixel-bot-2.0\commands\verification.py", line 134, in verify
    await member_tup[1].add_roles(self.verification_role)
  File "C:\Users\rchir\AppData\Local\Programs\Python\Python39\lib\site-packages\discord\member.py", line 777, in add_roles
    await req(guild_id, user_id, role.id, reason=reason)
AttributeError: 'NoneType' object has no attribute 'id'
NEW ERROR

Traceback (most recent call last):
  File "C:\Users\rchir\OneDrive\Desktop\Pixel-bot-2.0\events\error_handler.py", line 266, in on_slash_command_error
    raise error
  File "C:\Users\rchir\AppData\Local\Programs\Python\Python39\lib\site-packages\discord_slash\client.py", line 1353, in invoke_command
    await func.invoke(ctx, **args)
  File "C:\Users\rchir\AppData\Local\Programs\Python\Python39\lib\site-packages\discord_slash\model.py", line 209, in invoke
    return await self.func(self.cog, *args, **kwargs)
  File "C:\Users\rchir\OneDrive\Desktop\Pixel-bot-2.0\commands\verification.py", line 137, in verify
    await member_tup[1].add_roles(self.verification_role)
  File "C:\Users\rchir\AppData\Local\Programs\Python\Python39\lib\site-packages\discord\member.py", line 777, in add_roles
    await req(guild_id, user_id, role.id, reason=reason)
AttributeError: 'NoneType' object has no attribute 'id'
NEW ERROR

Traceback (most recent call last):
  File "C:\Users\rchir\OneDrive\Desktop\Pixel-bot-2.0\events\error_handler.py", line 266, in on_slash_command_error
    raise error
  File "C:\Users\rchir\AppData\Local\Programs\Python\Python39\lib\site-packages\discord_slash\client.py", line 1353, in invoke_command
    await func.invoke(ctx, **args)
  File "C:\Users\rchir\AppData\Local\Programs\Python\Python39\lib\site-packages\discord_slash\model.py", line 209, in invoke
    return await self.func(self.cog, *args, **kwargs)
  File "C:\Users\rchir\OneDrive\Desktop\Pixel-bot-2.0\commands\verification.py", line 138, in verify
    await member_tup[1].add_roles(self.verification_role)
  File "C:\Users\rchir\AppData\Local\Programs\Python\Python39\lib\site-packages\discord\member.py", line 777, in add_roles
    await req(guild_id, user_id, role.id, reason=reason)
AttributeError: 'NoneType' object has no attribute 'id'
NEW ERROR

Traceback (most recent call last):
  File "C:\Users\rchir\OneDrive\Desktop\Pixel-bot-2.0\events\error_handler.py", line 266, in on_slash_command_error
    raise error
  File "C:\Users\rchir\AppData\Local\Programs\Python\Python39\lib\site-packages\discord_slash\client.py", line 1353, in invoke_command
    await func.invoke(ctx, **args)
  File "C:\Users\rchir\AppData\Local\Programs\Python\Python39\lib\site-packages\discord_slash\model.py", line 209, in invoke
    return await self.func(self.cog, *args, **kwargs)
  File "C:\Users\rchir\OneDrive\Desktop\Pixel-bot-2.0\commands\verification.py", line 139, in verify
    await member_tup[1].add_roles(self.verification_role)
  File "C:\Users\rchir\AppData\Local\Programs\Python\Python39\lib\site-packages\discord\member.py", line 777, in add_roles
    await req(guild_id, user_id, role.id, reason=reason)
AttributeError: 'NoneType' object has no attribute 'id'
NEW ERROR

Traceback (most recent call last):
  File "C:\Users\rchir\OneDrive\Desktop\Pixel-bot-2.0\events\error_handler.py", line 266, in on_slash_command_error
    raise error
  File "C:\Users\rchir\AppData\Local\Programs\Python\Python39\lib\site-packages\discord_slash\client.py", line 1353, in invoke_command
    await func.invoke(ctx, **args)
  File "C:\Users\rchir\AppData\Local\Programs\Python\Python39\lib\site-packages\discord_slash\model.py", line 209, in invoke
    return await self.func(self.cog, *args, **kwargs)
  File "C:\Users\rchir\OneDrive\Desktop\Pixel-bot-2.0\commands\verification.py", line 139, in verify
    await member_tup[1].add_roles(self.verification_role)
  File "C:\Users\rchir\AppData\Local\Programs\Python\Python39\lib\site-packages\discord\member.py", line 777, in add_roles
    await req(guild_id, user_id, role.id, reason=reason)
AttributeError: 'NoneType' object has no attribute 'id'
NEW ERROR

Traceback (most recent call last):
  File "C:\Users\rchir\OneDrive\Desktop\Pixel-bot-2.0\events\error_handler.py", line 266, in on_slash_command_error
    raise error
  File "C:\Users\rchir\AppData\Local\Programs\Python\Python39\lib\site-packages\discord_slash\client.py", line 1353, in invoke_command
    await func.invoke(ctx, **args)
  File "C:\Users\rchir\AppData\Local\Programs\Python\Python39\lib\site-packages\discord_slash\model.py", line 209, in invoke
    return await self.func(self.cog, *args, **kwargs)
  File "C:\Users\rchir\OneDrive\Desktop\Pixel-bot-2.0\commands\verification.py", line 140, in verify
    await member_tup[1].add_roles(self.verification_role)
  File "C:\Users\rchir\AppData\Local\Programs\Python\Python39\lib\site-packages\discord\member.py", line 777, in add_roles
    await req(guild_id, user_id, role.id, reason=reason)
AttributeError: 'NoneType' object has no attribute 'id'
NEW ERROR

Traceback (most recent call last):
  File "C:\Users\rchir\OneDrive\Desktop\Pixel-bot-2.0\events\error_handler.py", line 266, in on_slash_command_error
    raise error
  File "C:\Users\rchir\AppData\Local\Programs\Python\Python39\lib\site-packages\discord_slash\client.py", line 1353, in invoke_command
    await func.invoke(ctx, **args)
  File "C:\Users\rchir\AppData\Local\Programs\Python\Python39\lib\site-packages\discord_slash\model.py", line 209, in invoke
    return await self.func(self.cog, *args, **kwargs)
  File "C:\Users\rchir\OneDrive\Desktop\Pixel-bot-2.0\commands\verification.py", line 140, in verify
    await member_tup[1].add_roles(self.verification_role)
  File "C:\Users\rchir\AppData\Local\Programs\Python\Python39\lib\site-packages\discord\member.py", line 777, in add_roles
    await req(guild_id, user_id, role.id, reason=reason)
AttributeError: 'NoneType' object has no attribute 'id'
NEW ERROR

Traceback (most recent call last):
  File "C:\Users\rchir\OneDrive\Desktop\Pixel-bot-2.0\events\error_handler.py", line 266, in on_slash_command_error
    raise error
  File "C:\Users\rchir\AppData\Local\Programs\Python\Python39\lib\site-packages\discord_slash\client.py", line 1353, in invoke_command
    await func.invoke(ctx, **args)
  File "C:\Users\rchir\AppData\Local\Programs\Python\Python39\lib\site-packages\discord_slash\model.py", line 209, in invoke
    return await self.func(self.cog, *args, **kwargs)
  File "C:\Users\rchir\OneDrive\Desktop\Pixel-bot-2.0\commands\verification.py", line 159, in verify
    em = discord.Embed(color=self.cient.success if fail < success else self.client.failure,
AttributeError: 'Verification' object has no attribute 'cient'
NEW ERROR

Traceback (most recent call last):
  File "C:\Users\rchir\AppData\Local\Programs\Python\Python39\lib\asyncio\tasks.py", line 492, in wait_for
    fut.result()
asyncio.exceptions.CancelledError

The above exception was the direct cause of the following exception:

Traceback (most recent call last):
  File "C:\Users\rchir\OneDrive\Desktop\Pixel-bot-2.0\utils\paginator.py", line 79, in run
    button_ctx: ComponentContext = await manage_components.wait_for_component(
  File "C:\Users\rchir\AppData\Local\Programs\Python\Python39\lib\site-packages\discord_slash\utils\manage_components.py", line 323, in wait_for_component
    return await client.wait_for("component", check=_check, timeout=timeout)
  File "C:\Users\rchir\AppData\Local\Programs\Python\Python39\lib\asyncio\tasks.py", line 494, in wait_for
    raise exceptions.TimeoutError() from exc
asyncio.exceptions.TimeoutError

During handling of the above exception, another exception occurred:

Traceback (most recent call last):
  File "C:\Users\rchir\OneDrive\Desktop\Pixel-bot-2.0\events\error_handler.py", line 269, in on_slash_command_error
    raise error
  File "C:\Users\rchir\AppData\Local\Programs\Python\Python39\lib\site-packages\discord_slash\client.py", line 1353, in invoke_command
    await func.invoke(ctx, **args)
  File "C:\Users\rchir\AppData\Local\Programs\Python\Python39\lib\site-packages\discord_slash\model.py", line 209, in invoke
    return await self.func(self.cog, *args, **kwargs)
  File "C:\Users\rchir\OneDrive\Desktop\Pixel-bot-2.0\commands\games\mc_madness.py", line 908, in mm_questions
    await Paginator(embeds, ctx).run()
  File "C:\Users\rchir\OneDrive\Desktop\Pixel-bot-2.0\utils\paginator.py", line 109, in run
    await msg.edit(embed=self._iterable[page], components=[timeout_action_row])
AttributeError: 'dict' object has no attribute 'edit'
NEW ERROR

Traceback (most recent call last):
  File "C:\Users\rchir\OneDrive\Desktop\Pixel-bot-2.0\events\error_handler.py", line 269, in on_slash_command_error
    raise error
  File "C:\Users\rchir\AppData\Local\Programs\Python\Python39\lib\site-packages\discord_slash\client.py", line 1353, in invoke_command
    await func.invoke(ctx, **args)
  File "C:\Users\rchir\AppData\Local\Programs\Python\Python39\lib\site-packages\discord_slash\model.py", line 209, in invoke
    return await self.func(self.cog, *args, **kwargs)
  File "C:\Users\rchir\OneDrive\Desktop\Pixel-bot-2.0\commands\games\mc_madness.py", line 914, in mm_questions
    await Paginator(embeds, ctx).run()
  File "C:\Users\rchir\OneDrive\Desktop\Pixel-bot-2.0\utils\paginator.py", line 76, in run
    pprint.pprint(msg)
AttributeError: 'function' object has no attribute 'pprint'
NEW ERROR

Traceback (most recent call last):
  File "C:\Users\rchir\AppData\Local\Programs\Python\Python39\lib\asyncio\tasks.py", line 492, in wait_for
    fut.result()
asyncio.exceptions.CancelledError

The above exception was the direct cause of the following exception:

Traceback (most recent call last):
  File "C:\Users\rchir\OneDrive\Desktop\Pixel-bot-2.0\utils\paginator.py", line 83, in run
    button_ctx: ComponentContext = await manage_components.wait_for_component(
  File "C:\Users\rchir\AppData\Local\Programs\Python\Python39\lib\site-packages\discord_slash\utils\manage_components.py", line 323, in wait_for_component
    return await client.wait_for("component", check=_check, timeout=timeout)
  File "C:\Users\rchir\AppData\Local\Programs\Python\Python39\lib\asyncio\tasks.py", line 494, in wait_for
    raise exceptions.TimeoutError() from exc
asyncio.exceptions.TimeoutError

During handling of the above exception, another exception occurred:

Traceback (most recent call last):
  File "C:\Users\rchir\OneDrive\Desktop\Pixel-bot-2.0\events\error_handler.py", line 269, in on_slash_command_error
    raise error
  File "C:\Users\rchir\AppData\Local\Programs\Python\Python39\lib\site-packages\discord_slash\client.py", line 1353, in invoke_command
    await func.invoke(ctx, **args)
  File "C:\Users\rchir\AppData\Local\Programs\Python\Python39\lib\site-packages\discord_slash\model.py", line 209, in invoke
    return await self.func(self.cog, *args, **kwargs)
  File "C:\Users\rchir\OneDrive\Desktop\Pixel-bot-2.0\commands\games\mc_madness.py", line 914, in mm_questions
    await Paginator(embeds, ctx).run()
  File "C:\Users\rchir\OneDrive\Desktop\Pixel-bot-2.0\utils\paginator.py", line 114, in run
    await button_ctx.edit_origin(embed=self._iterable[page], components=[timeout_action_row])
AttributeError: 'NoneType' object has no attribute 'edit_origin'
NEW ERROR

Traceback (most recent call last):
  File "C:\Users\rchir\AppData\Local\Programs\Python\Python39\lib\asyncio\tasks.py", line 492, in wait_for
    fut.result()
asyncio.exceptions.CancelledError

The above exception was the direct cause of the following exception:

Traceback (most recent call last):
  File "C:\Users\rchir\OneDrive\Desktop\Pixel-bot-2.0\utils\paginator.py", line 81, in run
    button_ctx: ComponentContext = await manage_components.wait_for_component(
  File "C:\Users\rchir\AppData\Local\Programs\Python\Python39\lib\site-packages\discord_slash\utils\manage_components.py", line 323, in wait_for_component
    return await client.wait_for("component", check=_check, timeout=timeout)
  File "C:\Users\rchir\AppData\Local\Programs\Python\Python39\lib\asyncio\tasks.py", line 494, in wait_for
    raise exceptions.TimeoutError() from exc
asyncio.exceptions.TimeoutError

During handling of the above exception, another exception occurred:

Traceback (most recent call last):
  File "C:\Users\rchir\OneDrive\Desktop\Pixel-bot-2.0\events\error_handler.py", line 269, in on_slash_command_error
    raise error
  File "C:\Users\rchir\AppData\Local\Programs\Python\Python39\lib\site-packages\discord_slash\client.py", line 1353, in invoke_command
    await func.invoke(ctx, **args)
  File "C:\Users\rchir\AppData\Local\Programs\Python\Python39\lib\site-packages\discord_slash\model.py", line 209, in invoke
    return await self.func(self.cog, *args, **kwargs)
  File "C:\Users\rchir\OneDrive\Desktop\Pixel-bot-2.0\commands\games\mc_madness.py", line 914, in mm_questions
    await Paginator(embeds, ctx).run()
  File "C:\Users\rchir\OneDrive\Desktop\Pixel-bot-2.0\utils\paginator.py", line 114, in run
    await self.button_ctx.edit_origin(embed=self._iterable[page], components=[timeout_action_row])
AttributeError: 'Paginator' object has no attribute 'button_ctx'
NEW ERROR

Traceback (most recent call last):
  File "C:\Users\rchir\AppData\Local\Programs\Python\Python39\lib\asyncio\tasks.py", line 492, in wait_for
    fut.result()
asyncio.exceptions.CancelledError

The above exception was the direct cause of the following exception:

Traceback (most recent call last):
  File "C:\Users\rchir\OneDrive\Desktop\Pixel-bot-2.0\utils\paginator.py", line 81, in run
    button_ctx: ComponentContext = await manage_components.wait_for_component(
  File "C:\Users\rchir\AppData\Local\Programs\Python\Python39\lib\site-packages\discord_slash\utils\manage_components.py", line 323, in wait_for_component
    return await client.wait_for("component", check=_check, timeout=timeout)
  File "C:\Users\rchir\AppData\Local\Programs\Python\Python39\lib\asyncio\tasks.py", line 494, in wait_for
    raise exceptions.TimeoutError() from exc
asyncio.exceptions.TimeoutError

During handling of the above exception, another exception occurred:

Traceback (most recent call last):
  File "C:\Users\rchir\OneDrive\Desktop\Pixel-bot-2.0\events\error_handler.py", line 269, in on_slash_command_error
    raise error
  File "C:\Users\rchir\AppData\Local\Programs\Python\Python39\lib\site-packages\discord_slash\client.py", line 1353, in invoke_command
    await func.invoke(ctx, **args)
  File "C:\Users\rchir\AppData\Local\Programs\Python\Python39\lib\site-packages\discord_slash\model.py", line 209, in invoke
    return await self.func(self.cog, *args, **kwargs)
  File "C:\Users\rchir\OneDrive\Desktop\Pixel-bot-2.0\commands\games\mc_madness.py", line 914, in mm_questions
    await Paginator(embeds, ctx).run()
  File "C:\Users\rchir\OneDrive\Desktop\Pixel-bot-2.0\utils\paginator.py", line 114, in run
    await self.my_button_ctx.edit_origin(embed=self._iterable[page], components=[timeout_action_row])
  File "C:\Users\rchir\AppData\Local\Programs\Python\Python39\lib\site-packages\discord_slash\context.py", line 626, in edit_origin
    raise error.IncorrectFormat("Already responded")
discord_slash.error.IncorrectFormat: Already responded
NEW ERROR

Traceback (most recent call last):
  File "C:\Users\rchir\AppData\Local\Programs\Python\Python39\lib\asyncio\tasks.py", line 492, in wait_for
    fut.result()
asyncio.exceptions.CancelledError

The above exception was the direct cause of the following exception:

Traceback (most recent call last):
  File "C:\Users\rchir\OneDrive\Desktop\Pixel-bot-2.0\utils\paginator.py", line 81, in run
    button_ctx: ComponentContext = await manage_components.wait_for_component(
  File "C:\Users\rchir\AppData\Local\Programs\Python\Python39\lib\site-packages\discord_slash\utils\manage_components.py", line 323, in wait_for_component
    return await client.wait_for("component", check=_check, timeout=timeout)
  File "C:\Users\rchir\AppData\Local\Programs\Python\Python39\lib\asyncio\tasks.py", line 494, in wait_for
    raise exceptions.TimeoutError() from exc
asyncio.exceptions.TimeoutError

During handling of the above exception, another exception occurred:

Traceback (most recent call last):
  File "C:\Users\rchir\OneDrive\Desktop\Pixel-bot-2.0\events\error_handler.py", line 269, in on_slash_command_error
    raise error
  File "C:\Users\rchir\AppData\Local\Programs\Python\Python39\lib\site-packages\discord_slash\client.py", line 1353, in invoke_command
    await func.invoke(ctx, **args)
  File "C:\Users\rchir\AppData\Local\Programs\Python\Python39\lib\site-packages\discord_slash\model.py", line 209, in invoke
    return await self.func(self.cog, *args, **kwargs)
  File "C:\Users\rchir\OneDrive\Desktop\Pixel-bot-2.0\commands\games\mc_madness.py", line 914, in mm_questions
    await Paginator(embeds, ctx).run()
  File "C:\Users\rchir\OneDrive\Desktop\Pixel-bot-2.0\utils\paginator.py", line 114, in run
    await self.my_button_ctx.edit_origin(embed=self._iterable[page], components=[timeout_action_row])
  File "C:\Users\rchir\AppData\Local\Programs\Python\Python39\lib\site-packages\discord_slash\context.py", line 626, in edit_origin
    raise error.IncorrectFormat("Already responded")
discord_slash.error.IncorrectFormat: Already responded
