Traceback (most recent call last):
  File "C:\Users\rchir\AppData\Local\Programs\Python\Python39\lib\asyncio\tasks.py", line 492, in wait_for
    fut.result()
asyncio.exceptions.CancelledError

The above exception was the direct cause of the following exception:

Traceback (most recent call last):
  File "C:\Users\rchir\OneDrive\Desktop\Pixel-bot-2.0\utils\paginator.py", line 81, in run
    button_ctx: ComponentContext = await manage_components.wait_for_component(
  File "C:\Users\rchir\AppData\Local\Programs\Python\Python39\lib\site-packages\discord_slash\utils\manage_components.py", line 323, in wait_for_component
    return await client.wait_for("component", check=_check, timeout=timeout)
  File "C:\Users\rchir\AppData\Local\Programs\Python\Python39\lib\asyncio\tasks.py", line 494, in wait_for
    raise exceptions.TimeoutError() from exc
asyncio.exceptions.TimeoutError

During handling of the above exception, another exception occurred:

Traceback (most recent call last):
  File "C:\Users\rchir\OneDrive\Desktop\Pixel-bot-2.0\events\error_handler.py", line 269, in on_slash_command_error
    raise error
  File "C:\Users\rchir\AppData\Local\Programs\Python\Python39\lib\site-packages\discord_slash\client.py", line 1353, in invoke_command
    await func.invoke(ctx, **args)
  File "C:\Users\rchir\AppData\Local\Programs\Python\Python39\lib\site-packages\discord_slash\model.py", line 209, in invoke
    return await self.func(self.cog, *args, **kwargs)
  File "C:\Users\rchir\OneDrive\Desktop\Pixel-bot-2.0\commands\games\mc_madness.py", line 914, in mm_questions
    await Paginator(embeds, ctx).run()
  File "C:\Users\rchir\OneDrive\Desktop\Pixel-bot-2.0\utils\paginator.py", line 114, in run
    await self.my_button_ctx.edit_origin(embed=self._iterable[page], components=[timeout_action_row])
  File "C:\Users\rchir\AppData\Local\Programs\Python\Python39\lib\site-packages\discord_slash\context.py", line 626, in edit_origin
    raise error.IncorrectFormat("Already responded")
discord_slash.error.IncorrectFormat: Already responded
Traceback (most recent call last):
  File "C:\Users\rchir\AppData\Local\Programs\Python\Python39\lib\asyncio\tasks.py", line 492, in wait_for
    fut.result()
asyncio.exceptions.CancelledError

The above exception was the direct cause of the following exception:

Traceback (most recent call last):
  File "C:\Users\rchir\OneDrive\Desktop\Pixel-bot-2.0\utils\paginator.py", line 81, in run
    button_ctx: ComponentContext = await manage_components.wait_for_component(
  File "C:\Users\rchir\AppData\Local\Programs\Python\Python39\lib\site-packages\discord_slash\utils\manage_components.py", line 323, in wait_for_component
    return await client.wait_for("component", check=_check, timeout=timeout)
  File "C:\Users\rchir\AppData\Local\Programs\Python\Python39\lib\asyncio\tasks.py", line 494, in wait_for
    raise exceptions.TimeoutError() from exc
asyncio.exceptions.TimeoutError

During handling of the above exception, another exception occurred:

Traceback (most recent call last):
  File "C:\Users\rchir\OneDrive\Desktop\Pixel-bot-2.0\events\error_handler.py", line 269, in on_slash_command_error
    raise error
  File "C:\Users\rchir\AppData\Local\Programs\Python\Python39\lib\site-packages\discord_slash\client.py", line 1353, in invoke_command
    await func.invoke(ctx, **args)
  File "C:\Users\rchir\AppData\Local\Programs\Python\Python39\lib\site-packages\discord_slash\model.py", line 209, in invoke
    return await self.func(self.cog, *args, **kwargs)
  File "C:\Users\rchir\OneDrive\Desktop\Pixel-bot-2.0\commands\games\mc_madness.py", line 914, in mm_questions
    await Paginator(embeds, ctx).run()
  File "C:\Users\rchir\OneDrive\Desktop\Pixel-bot-2.0\utils\paginator.py", line 114, in run
    await self.my_button_ctx.edit_origin(embed=self._iterable[page], components=[timeout_action_row])
  File "C:\Users\rchir\AppData\Local\Programs\Python\Python39\lib\site-packages\discord_slash\context.py", line 626, in edit_origin
    raise error.IncorrectFormat("Already responded")
discord_slash.error.IncorrectFormat: Already responded
